Workbook

Sheet Summary
A1: ="Hub Operations Dashboard: "&Assumptions!B3 -> Hub Operations Dashboard: Northgate Sort Hub (fictitious)
A2: ="Window: "&TEXT('Daily Data'!A5,"d mmm")&" to "&TEXT('Daily Data'!A34,"d mmm yyyy")&" (30 operating days) | Data through "&TEXT(ReportDate,"d mmm yyyy")&" | Hub "&Assumptions!B4&" | Sample data" -> Window: 14 Sep to 17 Oct 2026 (30 operating days) | Data through 17 Oct 2026 | Hub NGH-01 | Sample data
A3: Service filter | B3: All | E3: Zone filter | F3: All | I3: Data through | J3: =ReportDate -> 46312 | L3: auto
A5: PARCELS RECEIVED (30d) | D5: ATTEMPT RATE | G5: DELIVERY SLA | J5: CLOSING BACKLOG
A6: ='Daily Data'!C35 -> 7963 | D6: ='Daily Data'!H35 -> 0.98160708 | G6: ='Daily Data'!J35 -> 0.97577406 | J6: ='Daily Data'!M34 -> 458
A7: ="Avg "&TEXT(AVERAGE('Daily Data'!C5:C34),"#,##0")&" per operating day" -> Avg 265 per operating day | D7: ="Target "&TEXT(Att_Target,"0.0%")&IF('Daily Data'!H35>=Att_Target," - on target"," - below target") -> Target 97.0% - on target | G7: ="Target "&TEXT(SLA_Target,"0.0%")&IF('Daily Data'!J35>=SLA_Target," - on target"," - below target") -> Target 95.0% - on target | J7: =IF('Daily Data'!C35=0,"",TEXT('Daily Data'!M34/AVERAGE('Daily Data'!C5:C34),"0.0")&" days of avg intake") -> 1.7 days of avg intake
A9: Performance snapshot
A10: Metric | D10: Report day | F10: Last 7 days | H10: 30 days | J10: Target | K10: Status (7d)
A11: Parcels received per day | D11: ='Daily Data'!C34 -> 168 | F11: =AVERAGE('Daily Data'!C28:C34) -> 244 | H11: =AVERAGE('Daily Data'!C5:C34) -> 265.43333 | J11: - | K11: -
A12: Attempt rate | D12: ='Daily Data'!H34 -> 0.99555556 | F12: =IF(SUM('Daily Data'!D28:D34)=0,0,SUM('Daily Data'!E28:E34)/SUM('Daily Data'!D28:D34)) -> 0.98609779 | H12: ='Daily Data'!H35 -> 0.98160708 | J12: =Att_Target -> 0.97 | K12: =IF(F12>=Att_Target,"On target",IF(F12>=Att_Target-0.02,"Watch","Below")) -> On target
A13: First-attempt delivery rate | D13: ='Daily Data'!P34 -> 0.89302326 | F13: =IF(SUM('Daily Data'!O28:O34)=0,0,SUM('Daily Data'!N28:N34)/SUM('Daily Data'!O28:O34)) -> 0.91090713 | H13: ='Daily Data'!P35 -> 0.90620155 | J13: =FA_Target -> 0.88 | K13: =IF(F13>=FA_Target,"On target",IF(F13>=FA_Target-0.02,"Watch","Below")) -> On target
A14: Delivery SLA % | D14: ='Daily Data'!J34 -> 0.96482412 | F14: =IF(SUM('Daily Data'!F28:F34)=0,0,SUM('Daily Data'!G28:G34)/SUM('Daily Data'!F28:F34)) -> 0.93351206 | H14: ='Daily Data'!J35 -> 0.97577406 | J14: =SLA_Target -> 0.95 | K14: =IF(F14>=SLA_Target,"On target",IF(F14>=SLA_Target-0.02,"Watch","Below")) -> Watch
A15: Closing backlog (parcels) | D15: ='Daily Data'!M34 -> 458 | F15: =AVERAGE('Daily Data'!M28:M34) -> 550.14286 | H15: =AVERAGE('Daily Data'!M5:M34) -> 400.46667 | J15: ="<= "&TEXT(Assumptions!B10,"0.0")&"d" -> <= 1.5d | K15: =IF('Daily Data'!C35=0,"-",IF(F15/AVERAGE('Daily Data'!C5:C34)<=Assumptions!B10,"On target",IF(F15/AVERAGE('Daily Data'!C5:C34)<=Assumptions!B10*1.5,"Watch","Below"))) -> Watch
A17: Zone performance (30 days, ignores Zone filter) | G17: Delivery exceptions (30 days)
A18: Zone | C18: Out for delivery | D18: Delivered | E18: SLA % | F18: Attempt rate | G18: Exception | J18: Count | K18: % of out for delivery
A19: North | C19: =COUNTIFS(A_Date,">="&'Daily Data'!$A$5,A_Date,"<="&'Daily Data'!$A$34,A_Zone,$A19,A_Svc,SvcCrit) -> 1944 | D19: =COUNTIFS(A_Date,">="&'Daily Data'!$A$5,A_Date,"<="&'Daily Data'!$A$34,A_Zone,$A19,A_Svc,SvcCrit,A_Out,"Delivered") -> 1739 | E19: =IF(D19=0,0,COUNTIFS(A_Date,">="&'Daily Data'!$A$5,A_Date,"<="&'Daily Data'!$A$34,A_Zone,$A19,A_Svc,SvcCrit,A_OT,1)/D19) -> 0.97527315 | F19: =IF(C19=0,0,COUNTIFS(A_Date,">="&'Daily Data'!$A$5,A_Date,"<="&'Daily Data'!$A$34,A_Zone,$A19,A_Svc,SvcCrit,A_Out,"<>Not attempted")/C19) -> 0.97993827 | G19: Customer not home | J19: =COUNTIFS(A_Date,">="&'Daily Data'!$A$5,A_Date,"<="&'Daily Data'!$A$34,A_Reason,$G19,A_Svc,SvcCrit,A_Zone,ZoneCrit) -> 423 | K19: =IF('Daily Data'!$D$35=0,0,J19/'Daily Data'!$D$35) -> 0.048626279
A20: South | C20: =COUNTIFS(A_Date,">="&'Daily Data'!$A$5,A_Date,"<="&'Daily Data'!$A$34,A_Zone,$A20,A_Svc,SvcCrit) -> 1777 | D20: =COUNTIFS(A_Date,">="&'Daily Data'!$A$5,A_Date,"<="&'Daily Data'!$A$34,A_Zone,$A20,A_Svc,SvcCrit,A_Out,"Delivered") -> 1569 | E20: =IF(D20=0,0,COUNTIFS(A_Date,">="&'Daily Data'!$A$5,A_Date,"<="&'Daily Data'!$A$34,A_Zone,$A20,A_Svc,SvcCrit,A_OT,1)/D20) -> 0.97450605 | F20: =IF(C20=0,0,COUNTIFS(A_Date,">="&'Daily Data'!$A$5,A_Date,"<="&'Daily Data'!$A$34,A_Zone,$A20,A_Svc,SvcCrit,A_Out,"<>Not attempted")/C20) -> 0.97861564 | G20: Address issue | J20: =COUNTIFS(A_Date,">="&'Daily Data'!$A$5,A_Date,"<="&'Daily Data'!$A$34,A_Reason,$G20,A_Svc,SvcCrit,A_Zone,ZoneCrit) -> 170 | K20: =IF('Daily Data'!$D$35=0,0,J20/'Daily Data'!$D$35) -> 0.019542476
A21: East | C21: =COUNTIFS(A_Date,">="&'Daily Data'!$A$5,A_Date,"<="&'Daily Data'!$A$34,A_Zone,$A21,A_Svc,SvcCrit) -> 1642 | D21: =COUNTIFS(A_Date,">="&'Daily Data'!$A$5,A_Date,"<="&'Daily Data'!$A$34,A_Zone,$A21,A_Svc,SvcCrit,A_Out,"Delivered") -> 1432 | E21: =IF(D21=0,0,COUNTIFS(A_Date,">="&'Daily Data'!$A$5,A_Date,"<="&'Daily Data'!$A$34,A_Zone,$A21,A_Svc,SvcCrit,A_OT,1)/D21) -> 0.97067039 | F21: =IF(C21=0,0,COUNTIFS(A_Date,">="&'Daily Data'!$A$5,A_Date,"<="&'Daily Data'!$A$34,A_Zone,$A21,A_Svc,SvcCrit,A_Out,"<>Not attempted")/C21) -> 0.98721072 | G21: Access issue | J21: =COUNTIFS(A_Date,">="&'Daily Data'!$A$5,A_Date,"<="&'Daily Data'!$A$34,A_Reason,$G21,A_Svc,SvcCrit,A_Zone,ZoneCrit) -> 131 | K21: =IF('Daily Data'!$D$35=0,0,J21/'Daily Data'!$D$35) -> 0.015059202
A22: West | C22: =COUNTIFS(A_Date,">="&'Daily Data'!$A$5,A_Date,"<="&'Daily Data'!$A$34,A_Zone,$A22,A_Svc,SvcCrit) -> 1510 | D22: =COUNTIFS(A_Date,">="&'Daily Data'!$A$5,A_Date,"<="&'Daily Data'!$A$34,A_Zone,$A22,A_Svc,SvcCrit,A_Out,"Delivered") -> 1312 | E22: =IF(D22=0,0,COUNTIFS(A_Date,">="&'Daily Data'!$A$5,A_Date,"<="&'Daily Data'!$A$34,A_Zone,$A22,A_Svc,SvcCrit,A_OT,1)/D22) -> 0.97179878 | F22: =IF(C22=0,0,COUNTIFS(A_Date,">="&'Daily Data'!$A$5,A_Date,"<="&'Daily Data'!$A$34,A_Zone,$A22,A_Svc,SvcCrit,A_Out,"<>Not attempted")/C22) -> 0.98410596 | G22: Refused by customer | J22: =COUNTIFS(A_Date,">="&'Daily Data'!$A$5,A_Date,"<="&'Daily Data'!$A$34,A_Reason,$G22,A_Svc,SvcCrit,A_Zone,ZoneCrit) -> 96 | K22: =IF('Daily Data'!$D$35=0,0,J22/'Daily Data'!$D$35) -> 0.011035751
A23: Central | C23: =COUNTIFS(A_Date,">="&'Daily Data'!$A$5,A_Date,"<="&'Daily Data'!$A$34,A_Zone,$A23,A_Svc,SvcCrit) -> 1826 | D23: =COUNTIFS(A_Date,">="&'Daily Data'!$A$5,A_Date,"<="&'Daily Data'!$A$34,A_Zone,$A23,A_Svc,SvcCrit,A_Out,"Delivered") -> 1667 | E23: =IF(D23=0,0,COUNTIFS(A_Date,">="&'Daily Data'!$A$5,A_Date,"<="&'Daily Data'!$A$34,A_Zone,$A23,A_Svc,SvcCrit,A_OT,1)/D23) -> 0.985003 | F23: =IF(C23=0,0,COUNTIFS(A_Date,">="&'Daily Data'!$A$5,A_Date,"<="&'Daily Data'!$A$34,A_Zone,$A23,A_Svc,SvcCrit,A_Out,"<>Not attempted")/C23) -> 0.97918949 | G23: Route cut-off | J23: =COUNTIFS(A_Date,">="&'Daily Data'!$A$5,A_Date,"<="&'Daily Data'!$A$34,A_Reason,$G23,A_Svc,SvcCrit,A_Zone,ZoneCrit) -> 160 | K23: =IF('Daily Data'!$D$35=0,0,J23/'Daily Data'!$D$35) -> 0.018392919
A24: All zones | C24: =SUM(C19:C23) -> 8699 | D24: =SUM(D19:D23) -> 7719 | E24: =IF(D24=0,0,SUMPRODUCT(D19:D23,E19:E23)/D24) -> 0.97577406 | F24: =IF(C24=0,0,SUMPRODUCT(C19:C23,F19:F23)/C24) -> 0.98160708 | G24: All exceptions | J24: =SUM(J19:J23) -> 980 | K24: =SUM(K19:K23) -> 0.11265663
A26: Alerts & observations
A27: ="- Delivery SLA was below the "&TEXT(SLA_Target,"0%")&" target on "&COUNTIF('Daily Data'!J5:J34,"<"&SLA_Target)&" of 30 days; weakest day "&TEXT(INDEX('Daily Data'!A5:A34,MATCH(MIN('Daily Data'!J5:J34),'Daily Data'!J5:J34,0)),"ddd d mmm")&" at "&TEXT(MIN('Daily Data'!J5:J34),"0.0%")&"." -> - Delivery SLA was below the 95% target on 6 of 30 days; weakest day Sat 10 Oct at 84.1%.
A28: ="- Intake peaked at "&TEXT(MAX('Daily Data'!C5:C34),"#,##0")&" parcels on "&TEXT(INDEX('Daily Data'!A5:A34,MATCH(MAX('Daily Data'!C5:C34),'Daily Data'!C5:C34,0)),"ddd d mmm")&"; backlog peaked at "&TEXT(MAX('Daily Data'!M5:M34),"#,##0")&" on "&TEXT(INDEX('Daily Data'!A5:A34,MATCH(MAX('Daily Data'!M5:M34),'Daily Data'!M5:M34,0)),"ddd d mmm")&"." -> - Intake peaked at 393 parcels on Fri 2 Oct; backlog peaked at 652 on Sat 10 Oct.
A29: ="- Lowest attempt rate: "&TEXT(MIN('Daily Data'!H5:H34),"0.0%")&" on "&TEXT(INDEX('Daily Data'!A5:A34,MATCH(MIN('Daily Data'!H5:H34),'Daily Data'!H5:H34,0)),"ddd d mmm")&". Top exception: "&INDEX(G19:G23,MATCH(MAX(J19:J23),J19:J23,0))&" ("&TEXT(MAX(J19:J23),"#,##0")&" parcels)." -> - Lowest attempt rate: 87.3% on Fri 9 Oct. Top exception: Customer not home (423 parcels).
A59: Sample data for illustration only. Paste new exports into 'Parcels' and 'Attempts'; this page refreshes by itself.

Sheet Daily Data
A1: Daily Operations Data (calculated from Parcels and Attempts)
A2: Rolling window of the last 30 operating days (Mon to Sat) ending on the report date. Respects the Service and Zone filters on Summary. Do not type here.
A4: Date | B4: Day | C4: Parcels Received | D4: Out for Delivery | E4: Attempted | F4: Delivered | G4: Delivered On Time | H4: Attempt Rate | I4: Delivery Success Rate | J4: Delivery SLA % | K4: SLA Target | L4: Attempt Target | M4: Closing Backlog | N4: 1st-Attempt Deliveries | O4: 1st Attempts | P4: 1st-Attempt Delivery Rate
A5: =A6-1-IF(WEEKDAY(A6-1,2)=7,1,0) -> 46279 | B5: =TEXT(A5,"ddd") -> Mon | C5: =COUNTIFS(P_Date,$A5,P_Svc,SvcCrit,P_Zone,ZoneCrit) -> 320 | D5: =COUNTIFS(A_Date,$A5,A_Svc,SvcCrit,A_Zone,ZoneCrit) -> 250 | E5: =COUNTIFS(A_Date,$A5,A_Out,"<>Not attempted",A_Svc,SvcCrit,A_Zone,ZoneCrit) -> 245 | F5: =COUNTIFS(A_Date,$A5,A_Out,"Delivered",A_Svc,SvcCrit,A_Zone,ZoneCrit) -> 228 | G5: =COUNTIFS(A_Date,$A5,A_OT,1,A_Svc,SvcCrit,A_Zone,ZoneCrit) -> 226 | H5: =IF(D5=0,0,E5/D5) -> 0.98 | I5: =IF(E5=0,0,F5/E5) -> 0.93061224 | J5: =IF(F5=0,0,G5/F5) -> 0.99122807 | K5: =SLA_Target -> 0.95 | L5: =Att_Target -> 0.97 | M5: =COUNTIFS(P_Date,"<="&$A5,P_Svc,SvcCrit,P_Zone,ZoneCrit)-COUNTIFS(A_Date,"<="&$A5,A_Out,"Delivered",A_Svc,SvcCrit,A_Zone,ZoneCrit) -> 306 | N5: =COUNTIFS(A_Date,$A5,A_Out,"Delivered",A_No,1,A_Svc,SvcCrit,A_Zone,ZoneCrit) -> 210 | O5: =COUNTIFS(A_Date,$A5,A_No,1,A_Svc,SvcCrit,A_Zone,ZoneCrit) -> 226 | P5: =IF(O5=0,0,N5/O5) -> 0.92920354
A6: =A7-1-IF(WEEKDAY(A7-1,2)=7,1,0) -> 46280 | B6: =TEXT(A6,"ddd") -> Tue | C6: =COUNTIFS(P_Date,$A6,P_Svc,SvcCrit,P_Zone,ZoneCrit) -> 280 | D6: =COUNTIFS(A_Date,$A6,A_Svc,SvcCrit,A_Zone,ZoneCrit) -> 306 | E6: =COUNTIFS(A_Date,$A6,A_Out,"<>Not attempted",A_Svc,SvcCrit,A_Zone,ZoneCrit) -> 301 | F6: =COUNTIFS(A_Date,$A6,A_Out,"Delivered",A_Svc,SvcCrit,A_Zone,ZoneCrit) -> 273 | G6: =COUNTIFS(A_Date,$A6,A_OT,1,A_Svc,SvcCrit,A_Zone,ZoneCrit) -> 271 | H6: =IF(D6=0,0,E6/D6) -> 0.98366013 | I6: =IF(E6=0,0,F6/E6) -> 0.90697674 | J6: =IF(F6=0,0,G6/F6) -> 0.99267399 | K6: =SLA_Target -> 0.95 | L6: =Att_Target -> 0.97 | M6: =COUNTIFS(P_Date,"<="&$A6,P_Svc,SvcCrit,P_Zone,ZoneCrit)-COUNTIFS(A_Date,"<="&$A6,A_Out,"Delivered",A_Svc,SvcCrit,A_Zone,ZoneCrit) -> 313 | N6: =COUNTIFS(A_Date,$A6,A_Out,"Delivered",A_No,1,A_Svc,SvcCrit,A_Zone,ZoneCrit) -> 257 | O6: =COUNTIFS(A_Date,$A6,A_No,1,A_Svc,SvcCrit,A_Zone,ZoneCrit) -> 283 | P6: =IF(O6=0,0,N6/O6) -> 0.90812721
A7: =A8-1-IF(WEEKDAY(A8-1,2)=7,1,0) -> 46281 | B7: =TEXT(A7,"ddd") -> Wed | C7: =COUNTIFS(P_Date,$A7,P_Svc,SvcCrit,P_Zone,ZoneCrit) -> 275 | D7: =COUNTIFS(A_Date,$A7,A_Svc,SvcCrit,A_Zone,ZoneCrit) -> 300 | E7: =COUNTIFS(A_Date,$A7,A_Out,"<>Not attempted",A_Svc,SvcCrit,A_Zone,ZoneCrit) -> 299 | F7: =COUNTIFS(A_Date,$A7,A_Out,"Delivered",A_Svc,SvcCrit,A_Zone,ZoneCrit) -> 275 | G7: =COUNTIFS(A_Date,$A7,A_OT,1,A_Svc,SvcCrit,A_Zone,ZoneCrit) -> 271 | H7: =IF(D7=0,0,E7/D7) -> 0.99666667 | I7: =IF(E7=0,0,F7/E7) -> 0.91973244 | J7: =IF(F7=0,0,G7/F7) -> 0.98545455 | K7: =SLA_Target -> 0.95 | L7: =Att_Target -> 0.97 | M7: =COUNTIFS(P_Date,"<="&$A7,P_Svc,SvcCrit,P_Zone,ZoneCrit)-COUNTIFS(A_Date,"<="&$A7,A_Out,"Delivered",A_Svc,SvcCrit,A_Zone,ZoneCrit) -> 313 | N7: =COUNTIFS(A_Date,$A7,A_Out,"Delivered",A_No,1,A_Svc,SvcCrit,A_Zone,ZoneCrit) -> 251 | O7: =COUNTIFS(A_Date,$A7,A_No,1,A_Svc,SvcCrit,A_Zone,ZoneCrit) -> 271 | P7: =IF(O7=0,0,N7/O7) -> 0.92619926
A8: =A9-1-IF(WEEKDAY(A9-1,2)=7,1,0) -> 46282 | B8: =TEXT(A8,"ddd") -> Thu | C8: =COUNTIFS(P_Date,$A8,P_Svc,SvcCrit,P_Zone,ZoneCrit) -> 246 | D8: =COUNTIFS(A_Date,$A8,A_Svc,SvcCrit,A_Zone,ZoneCrit) -> 300 | E8: =COUNTIFS(A_Date,$A8,A_Out,"<>Not attempted",A_Svc,SvcCrit,A_Zone,ZoneCrit) -> 294 | F8: =COUNTIFS(A_Date,$A8,A_Out,"Delivered",A_Svc,SvcCrit,A_Zone,ZoneCrit) -> 266 | G8: =COUNTIFS(A_Date,$A8,A_OT,1,A_Svc,SvcCrit,A_Zone,ZoneCrit) -> 264 | H8: =IF(D8=0,0,E8/D8) -> 0.98 | I8: =IF(E8=0,0,F8/E8) -> 0.9047619 | J8: =IF(F8=0,0,G8/F8) -> 0.9924812 | K8: =SLA_Target -> 0.95 | L8: =Att_Target -> 0.97 | M8: =COUNTIFS(P_Date,"<="&$A8,P_Svc,SvcCrit,P_Zone,ZoneCrit)-COUNTIFS(A_Date,"<="&$A8,A_Out,"Delivered",A_Svc,SvcCrit,A_Zone,ZoneCrit) -> 293 | N8: =COUNTIFS(A_Date,$A8,A_Out,"Delivered",A_No,1,A_Svc,SvcCrit,A_Zone,ZoneCrit) -> 247 | O8: =COUNTIFS(A_Date,$A8,A_No,1,A_Svc,SvcCrit,A_Zone,ZoneCrit) -> 272 | P8: =IF(O8=0,0,N8/O8) -> 0.90808824
A9: =A10-1-IF(WEEKDAY(A10-1,2)=7,1,0) -> 46283 | B9: =TEXT(A9,"ddd") -> Fri | C9: =COUNTIFS(P_Date,$A9,P_Svc,SvcCrit,P_Zone,ZoneCrit) -> 264 | D9: =COUNTIFS(A_Date,$A9,A_Svc,SvcCrit,A_Zone,ZoneCrit) -> 306 | E9: =COUNTIFS(A_Date,$A9,A_Out,"<>Not attempted",A_Svc,SvcCrit,A_Zone,ZoneCrit) -> 301 | F9: =COUNTIFS(A_Date,$A9,A_Out,"Delivered",A_Svc,SvcCrit,A_Zone,ZoneCrit) -> 272 | G9: =COUNTIFS(A_Date,$A9,A_OT,1,A_Svc,SvcCrit,A_Zone,ZoneCrit) -> 270 | H9: =IF(D9=0,0,E9/D9) -> 0.98366013 | I9: =IF(E9=0,0,F9/E9) -> 0.90365449 | J9: =IF(F9=0,0,G9/F9) -> 0.99264706 | K9: =SLA_Target -> 0.95 | L9: =Att_Target -> 0.97 | M9: =COUNTIFS(P_Date,"<="&$A9,P_Svc,SvcCrit,P_Zone,ZoneCrit)-COUNTIFS(A_Date,"<="&$A9,A_Out,"Delivered",A_Svc,SvcCrit,A_Zone,ZoneCrit) -> 285 | N9: =COUNTIFS(A_Date,$A9,A_Out,"Delivered",A_No,1,A_Svc,SvcCrit,A_Zone,ZoneCrit) -> 244 | O9: =COUNTIFS(A_Date,$A9,A_No,1,A_Svc,SvcCrit,A_Zone,ZoneCrit) -> 272 | P9: =IF(O9=0,0,N9/O9) -> 0.89705882
A10: =A11-1-IF(WEEKDAY(A11-1,2)=7,1,0) -> 46284 | B10: =TEXT(A10,"ddd") -> Sat | C10: =COUNTIFS(P_Date,$A10,P_Svc,SvcCrit,P_Zone,ZoneCrit) -> 199 | D10: =COUNTIFS(A_Date,$A10,A_Svc,SvcCrit,A_Zone,ZoneCrit) -> 225 | E10: =COUNTIFS(A_Date,$A10,A_Out,"<>Not attempted",A_Svc,SvcCrit,A_Zone,ZoneCrit) -> 224 | F10: =COUNTIFS(A_Date,$A10,A_Out,"Delivered",A_Svc,SvcCrit,A_Zone,ZoneCrit) -> 198 | G10: =COUNTIFS(A_Date,$A10,A_OT,1,A_Svc,SvcCrit,A_Zone,ZoneCrit) -> 197 | H10: =IF(D10=0,0,E10/D10) -> 0.99555556 | I10: =IF(E10=0,0,F10/E10) -> 0.88392857 | J10: =IF(F10=0,0,G10/F10) -> 0.99494949 | K10: =SLA_Target -> 0.95 | L10: =Att_Target -> 0.97 | M10: =COUNTIFS(P_Date,"<="&$A10,P_Svc,SvcCrit,P_Zone,ZoneCrit)-COUNTIFS(A_Date,"<="&$A10,A_Out,"Delivered",A_Svc,SvcCrit,A_Zone,ZoneCrit) -> 286 | N10: =COUNTIFS(A_Date,$A10,A_Out,"Delivered",A_No,1,A_Svc,SvcCrit,A_Zone,ZoneCrit) -> 171 | O10: =COUNTIFS(A_Date,$A10,A_No,1,A_Svc,SvcCrit,A_Zone,ZoneCrit) -> 194 | P10: =IF(O10=0,0,N10/O10) -> 0.8814433
A11: =A12-1-IF(WEEKDAY(A12-1,2)=7,1,0) -> 46286 | B11: =TEXT(A11,"ddd") -> Mon | C11: =COUNTIFS(P_Date,$A11,P_Svc,SvcCrit,P_Zone,ZoneCrit) -> 291 | D11: =COUNTIFS(A_Date,$A11,A_Svc,SvcCrit,A_Zone,ZoneCrit) -> 318 | E11: =COUNTIFS(A_Date,$A11,A_Out,"<>Not attempted",A_Svc,SvcCrit,A_Zone,ZoneCrit) -> 315 | F11: =COUNTIFS(A_Date,$A11,A_Out,"Delivered",A_Svc,SvcCrit,A_Zone,ZoneCrit) -> 288 | G11: =COUNTIFS(A_Date,$A11,A_OT,1,A_Svc,SvcCrit,A_Zone,ZoneCrit) -> 288 | H11: =IF(D11=0,0,E11/D11) -> 0.99056604 | I11: =IF(E11=0,0,F11/E11) -> 0.91428571 | J11: =IF(F11=0,0,G11/F11) -> 1 | K11: =SLA_Target -> 0.95 | L11: =Att_Target -> 0.97 | M11: =COUNTIFS(P_Date,"<="&$A11,P_Svc,SvcCrit,P_Zone,ZoneCrit)-COUNTIFS(A_Date,"<="&$A11,A_Out,"Delivered",A_Svc,SvcCrit,A_Zone,ZoneCrit) -> 289 | N11: =COUNTIFS(A_Date,$A11,A_Out,"Delivered",A_No,1,A_Svc,SvcCrit,A_Zone,ZoneCrit) -> 265 | O11: =COUNTIFS(A_Date,$A11,A_No,1,A_Svc,SvcCrit,A_Zone,ZoneCrit) -> 289 | P11: =IF(O11=0,0,N11/O11) -> 0.91695502
A12: =A13-1-IF(WEEKDAY(A13-1,2)=7,1,0) -> 46287 | B12: =TEXT(A12,"ddd") -> Tue | C12: =COUNTIFS(P_Date,$A12,P_Svc,SvcCrit,P_Zone,ZoneCrit) -> 252 | D12: =COUNTIFS(A_Date,$A12,A_Svc,SvcCrit,A_Zone,ZoneCrit) -> 306 | E12: =COUNTIFS(A_Date,$A12,A_Out,"<>Not attempted",A_Svc,SvcCrit,A_Zone,ZoneCrit) -> 302 | F12: =COUNTIFS(A_Date,$A12,A_Out,"Delivered",A_Svc,SvcCrit,A_Zone,ZoneCrit) -> 283 | G12: =COUNTIFS(A_Date,$A12,A_OT,1,A_Svc,SvcCrit,A_Zone,ZoneCrit) -> 279 | H12: =IF(D12=0,0,E12/D12) -> 0.9869281 | I12: =IF(E12=0,0,F12/E12) -> 0.93708609 | J12: =IF(F12=0,0,G12/F12) -> 0.98586572 | K12: =SLA_Target -> 0.95 | L12: =Att_Target -> 0.97 | M12: =COUNTIFS(P_Date,"<="&$A12,P_Svc,SvcCrit,P_Zone,ZoneCrit)-COUNTIFS(A_Date,"<="&$A12,A_Out,"Delivered",A_Svc,SvcCrit,A_Zone,ZoneCrit) -> 258 | N12: =COUNTIFS(A_Date,$A12,A_Out,"Delivered",A_No,1,A_Svc,SvcCrit,A_Zone,ZoneCrit) -> 256 | O12: =COUNTIFS(A_Date,$A12,A_No,1,A_Svc,SvcCrit,A_Zone,ZoneCrit) -> 275 | P12: =IF(O12=0,0,N12/O12) -> 0.93090909
A13: =A14-1-IF(WEEKDAY(A14-1,2)=7,1,0) -> 46288 | B13: =TEXT(A13,"ddd") -> Wed | C13: =COUNTIFS(P_Date,$A13,P_Svc,SvcCrit,P_Zone,ZoneCrit) -> 248 | D13: =COUNTIFS(A_Date,$A13,A_Svc,SvcCrit,A_Zone,ZoneCrit) -> 288 | E13: =COUNTIFS(A_Date,$A13,A_Out,"<>Not attempted",A_Svc,SvcCrit,A_Zone,ZoneCrit) -> 283 | F13: =COUNTIFS(A_Date,$A13,A_Out,"Delivered",A_Svc,SvcCrit,A_Zone,ZoneCrit) -> 252 | G13: =COUNTIFS(A_Date,$A13,A_OT,1,A_Svc,SvcCrit,A_Zone,ZoneCrit) -> 252 | H13: =IF(D13=0,0,E13/D13) -> 0.98263889 | I13: =IF(E13=0,0,F13/E13) -> 0.89045936 | J13: =IF(F13=0,0,G13/F13) -> 1 | K13: =SLA_Target -> 0.95 | L13: =Att_Target -> 0.97 | M13: =COUNTIFS(P_Date,"<="&$A13,P_Svc,SvcCrit,P_Zone,ZoneCrit)-COUNTIFS(A_Date,"<="&$A13,A_Out,"Delivered",A_Svc,SvcCrit,A_Zone,ZoneCrit) -> 254 | N13: =COUNTIFS(A_Date,$A13,A_Out,"Delivered",A_No,1,A_Svc,SvcCrit,A_Zone,ZoneCrit) -> 237 | O13: =COUNTIFS(A_Date,$A13,A_No,1,A_Svc,SvcCrit,A_Zone,ZoneCrit) -> 265 | P13: =IF(O13=0,0,N13/O13) -> 0.89433962
A14: =A15-1-IF(WEEKDAY(A15-1,2)=7,1,0) -> 46289 | B14: =TEXT(A14,"ddd") -> Thu | C14: =COUNTIFS(P_Date,$A14,P_Svc,SvcCrit,P_Zone,ZoneCrit) -> 269 | D14: =COUNTIFS(A_Date,$A14,A_Svc,SvcCrit,A_Zone,ZoneCrit) -> 282 | E14: =COUNTIFS(A_Date,$A14,A_Out,"<>Not attempted",A_Svc,SvcCrit,A_Zone,ZoneCrit) -> 276 | F14: =COUNTIFS(A_Date,$A14,A_Out,"Delivered",A_Svc,SvcCrit,A_Zone,ZoneCrit) -> 249 | G14: =COUNTIFS(A_Date,$A14,A_OT,1,A_Svc,SvcCrit,A_Zone,ZoneCrit) -> 247 | H14: =IF(D14=0,0,E14/D14) -> 0.9787234 | I14: =IF(E14=0,0,F14/E14) -> 0.90217391 | J14: =IF(F14=0,0,G14/F14) -> 0.99196787 | K14: =SLA_Target -> 0.95 | L14: =Att_Target -> 0.97 | M14: =COUNTIFS(P_Date,"<="&$A14,P_Svc,SvcCrit,P_Zone,ZoneCrit)-COUNTIFS(A_Date,"<="&$A14,A_Out,"Delivered",A_Svc,SvcCrit,A_Zone,ZoneCrit) -> 274 | N14: =COUNTIFS(A_Date,$A14,A_Out,"Delivered",A_No,1,A_Svc,SvcCrit,A_Zone,ZoneCrit) -> 224 | O14: =COUNTIFS(A_Date,$A14,A_No,1,A_Svc,SvcCrit,A_Zone,ZoneCrit) -> 245 | P14: =IF(O14=0,0,N14/O14) -> 0.91428571
A15: =A16-1-IF(WEEKDAY(A16-1,2)=7,1,0) -> 46290 | B15: =TEXT(A15,"ddd") -> Fri | C15: =COUNTIFS(P_Date,$A15,P_Svc,SvcCrit,P_Zone,ZoneCrit) -> 295 | D15: =COUNTIFS(A_Date,$A15,A_Svc,SvcCrit,A_Zone,ZoneCrit) -> 305 | E15: =COUNTIFS(A_Date,$A15,A_Out,"<>Not attempted",A_Svc,SvcCrit,A_Zone,ZoneCrit) -> 302 | F15: =COUNTIFS(A_Date,$A15,A_Out,"Delivered",A_Svc,SvcCrit,A_Zone,ZoneCrit) -> 272 | G15: =COUNTIFS(A_Date,$A15,A_OT,1,A_Svc,SvcCrit,A_Zone,ZoneCrit) -> 271 | H15: =IF(D15=0,0,E15/D15) -> 0.99016393 | I15: =IF(E15=0,0,F15/E15) -> 0.90066225 | J15: =IF(F15=0,0,G15/F15) -> 0.99632353 | K15: =SLA_Target -> 0.95 | L15: =Att_Target -> 0.97 | M15: =COUNTIFS(P_Date,"<="&$A15,P_Svc,SvcCrit,P_Zone,ZoneCrit)-COUNTIFS(A_Date,"<="&$A15,A_Out,"Delivered",A_Svc,SvcCrit,A_Zone,ZoneCrit) -> 297 | N15: =COUNTIFS(A_Date,$A15,A_Out,"Delivered",A_No,1,A_Svc,SvcCrit,A_Zone,ZoneCrit) -> 247 | O15: =COUNTIFS(A_Date,$A15,A_No,1,A_Svc,SvcCrit,A_Zone,ZoneCrit) -> 274 | P15: =IF(O15=0,0,N15/O15) -> 0.90145985
A16: =A17-1-IF(WEEKDAY(A17-1,2)=7,1,0) -> 46291 | B16: =TEXT(A16,"ddd") -> Sat | C16: =COUNTIFS(P_Date,$A16,P_Svc,SvcCrit,P_Zone,ZoneCrit) -> 191 | D16: =COUNTIFS(A_Date,$A16,A_Svc,SvcCrit,A_Zone,ZoneCrit) -> 225 | E16: =COUNTIFS(A_Date,$A16,A_Out,"<>Not attempted",A_Svc,SvcCrit,A_Zone,ZoneCrit) -> 220 | F16: =COUNTIFS(A_Date,$A16,A_Out,"Delivered",A_Svc,SvcCrit,A_Zone,ZoneCrit) -> 198 | G16: =COUNTIFS(A_Date,$A16,A_OT,1,A_Svc,SvcCrit,A_Zone,ZoneCrit) -> 196 | H16: =IF(D16=0,0,E16/D16) -> 0.97777778 | I16: =IF(E16=0,0,F16/E16) -> 0.9 | J16: =IF(F16=0,0,G16/F16) -> 0.98989899 | K16: =SLA_Target -> 0.95 | L16: =Att_Target -> 0.97 | M16: =COUNTIFS(P_Date,"<="&$A16,P_Svc,SvcCrit,P_Zone,ZoneCrit)-COUNTIFS(A_Date,"<="&$A16,A_Out,"Delivered",A_Svc,SvcCrit,A_Zone,ZoneCrit) -> 290 | N16: =COUNTIFS(A_Date,$A16,A_Out,"Delivered",A_No,1,A_Svc,SvcCrit,A_Zone,ZoneCrit) -> 173 | O16: =COUNTIFS(A_Date,$A16,A_No,1,A_Svc,SvcCrit,A_Zone,ZoneCrit) -> 191 | P16: =IF(O16=0,0,N16/O16) -> 0.90575916
... A33: =A34-1-IF(WEEKDAY(A34-1,2)=7,1,0) -> 46311 | B33: =TEXT(A33,"ddd") -> Fri | C33: =COUNTIFS(P_Date,$A33,P_Svc,SvcCrit,P_Zone,ZoneCrit) -> 267 | D33: =COUNTIFS(A_Date,$A33,A_Svc,SvcCrit,A_Zone,ZoneCrit) -> 321 | E33: =COUNTIFS(A_Date,$A33,A_Out,"<>Not attempted",A_Svc,SvcCrit,A_Zone,ZoneCrit) -> 317 | F33: =COUNTIFS(A_Date,$A33,A_Out,"Delivered",A_Svc,SvcCrit,A_Zone,ZoneCrit) -> 298 | G33: =COUNTIFS(A_Date,$A33,A_OT,1,A_Svc,SvcCrit,A_Zone,ZoneCrit) -> 282 | H33: =IF(D33=0,0,E33/D33) -> 0.98753894 | I33: =IF(E33=0,0,F33/E33) -> 0.94006309 | J33: =IF(F33=0,0,G33/F33) -> 0.94630872 | K33: =SLA_Target -> 0.95 | L33: =Att_Target -> 0.97 | M33: =COUNTIFS(P_Date,"<="&$A33,P_Svc,SvcCrit,P_Zone,ZoneCrit)-COUNTIFS(A_Date,"<="&$A33,A_Out,"Delivered",A_Svc,SvcCrit,A_Zone,ZoneCrit) -> 489 | N33: =COUNTIFS(A_Date,$A33,A_Out,"Delivered",A_No,1,A_Svc,SvcCrit,A_Zone,ZoneCrit) -> 267 | O33: =COUNTIFS(A_Date,$A33,A_No,1,A_Svc,SvcCrit,A_Zone,ZoneCrit) -> 283 | P33: =IF(O33=0,0,N33/O33) -> 0.9434629
A34: =ReportDate-IF(WEEKDAY(ReportDate,2)=7,1,0) -> 46312 | B34: =TEXT(A34,"ddd") -> Sat | C34: =COUNTIFS(P_Date,$A34,P_Svc,SvcCrit,P_Zone,ZoneCrit) -> 168 | D34: =COUNTIFS(A_Date,$A34,A_Svc,SvcCrit,A_Zone,ZoneCrit) -> 225 | E34: =COUNTIFS(A_Date,$A34,A_Out,"<>Not attempted",A_Svc,SvcCrit,A_Zone,ZoneCrit) -> 224 | F34: =COUNTIFS(A_Date,$A34,A_Out,"Delivered",A_Svc,SvcCrit,A_Zone,ZoneCrit) -> 199 | G34: =COUNTIFS(A_Date,$A34,A_OT,1,A_Svc,SvcCrit,A_Zone,ZoneCrit) -> 192 | H34: =IF(D34=0,0,E34/D34) -> 0.99555556 | I34: =IF(E34=0,0,F34/E34) -> 0.88839286 | J34: =IF(F34=0,0,G34/F34) -> 0.96482412 | K34: =SLA_Target -> 0.95 | L34: =Att_Target -> 0.97 | M34: =COUNTIFS(P_Date,"<="&$A34,P_Svc,SvcCrit,P_Zone,ZoneCrit)-COUNTIFS(A_Date,"<="&$A34,A_Out,"Delivered",A_Svc,SvcCrit,A_Zone,ZoneCrit) -> 458 | N34: =COUNTIFS(A_Date,$A34,A_Out,"Delivered",A_No,1,A_Svc,SvcCrit,A_Zone,ZoneCrit) -> 192 | O34: =COUNTIFS(A_Date,$A34,A_No,1,A_Svc,SvcCrit,A_Zone,ZoneCrit) -> 215 | P34: =IF(O34=0,0,N34/O34) -> 0.89302326
A35: Total / overall | C35: =SUM(C5:C34) -> 7963 | D35: =SUM(D5:D34) -> 8699 | E35: =SUM(E5:E34) -> 8539 | F35: =SUM(F5:F34) -> 7719 | G35: =SUM(G5:G34) -> 7532 | H35: =IF(D35=0,0,E35/D35) -> 0.98160708 | I35: =IF(E35=0,0,F35/E35) -> 0.90397002 | J35: =IF(F35=0,0,G35/F35) -> 0.97577406 | M35: =M34 -> 458 | N35: =SUM(N5:N34) -> 7014 | O35: =SUM(O5:O34) -> 7740 | P35: =IF(O35=0,0,N35/O35) -> 0.90620155

Sheet Parcels
A1: Parcel ID | B1: Received Date | C1: Service | D1: Zone | E1: Weight (kg) | F1: SLA Days | G1: SLA Due Date
A2: 1000001 | B2: 46273 | C2: Express | D2: North | E2: 2 | F2: =IF(A2="","",INDEX(Assumptions!$B$16:$B$18,MATCH(C2,Assumptions!$A$16:$A$18,0))) -> 1 | G2: =IF(A2="","",WORKDAY(B2,F2)) -> 46274
A3: 1000002 | B3: 46273 | C3: Standard | D3: North | E3: 1.7 | F3: =IF(A3="","",INDEX(Assumptions!$B$16:$B$18,MATCH(C3,Assumptions!$A$16:$A$18,0))) -> 3 | G3: =IF(A3="","",WORKDAY(B3,F3)) -> 46276
A4: 1000003 | B4: 46273 | C4: Standard | D4: East | E4: 2.9 | F4: =IF(A4="","",INDEX(Assumptions!$B$16:$B$18,MATCH(C4,Assumptions!$A$16:$A$18,0))) -> 3 | G4: =IF(A4="","",WORKDAY(B4,F4)) -> 46276
A5: 1000004 | B5: 46273 | C5: Standard | D5: West | E5: 6.5 | F5: =IF(A5="","",INDEX(Assumptions!$B$16:$B$18,MATCH(C5,Assumptions!$A$16:$A$18,0))) -> 3 | G5: =IF(A5="","",WORKDAY(B5,F5)) -> 46276
A6: 1000005 | B6: 46273 | C6: Standard | D6: Central | E6: 1.4 | F6: =IF(A6="","",INDEX(Assumptions!$B$16:$B$18,MATCH(C6,Assumptions!$A$16:$A$18,0))) -> 3 | G6: =IF(A6="","",WORKDAY(B6,F6)) -> 46276
A7: 1000006 | B7: 46273 | C7: Standard | D7: South | E7: 2.9 | F7: =IF(A7="","",INDEX(Assumptions!$B$16:$B$18,MATCH(C7,Assumptions!$A$16:$A$18,0))) -> 3 | G7: =IF(A7="","",WORKDAY(B7,F7)) -> 46276
A8: 1000007 | B8: 46273 | C8: Standard | D8: West | E8: 1.3 | F8: =IF(A8="","",INDEX(Assumptions!$B$16:$B$18,MATCH(C8,Assumptions!$A$16:$A$18,0))) -> 3 | G8: =IF(A8="","",WORKDAY(B8,F8)) -> 46276
A9: 1000008 | B9: 46273 | C9: Standard | D9: North | E9: 0.6 | F9: =IF(A9="","",INDEX(Assumptions!$B$16:$B$18,MATCH(C9,Assumptions!$A$16:$A$18,0))) -> 3 | G9: =IF(A9="","",WORKDAY(B9,F9)) -> 46276
A10: 1000009 | B10: 46273 | C10: Standard | D10: South | E10: 2.2 | F10: =IF(A10="","",INDEX(Assumptions!$B$16:$B$18,MATCH(C10,Assumptions!$A$16:$A$18,0))) -> 3 | G10: =IF(A10="","",WORKDAY(B10,F10)) -> 46276
A11: 1000010 | B11: 46273 | C11: Standard | D11: Central | E11: 2.5 | F11: =IF(A11="","",INDEX(Assumptions!$B$16:$B$18,MATCH(C11,Assumptions!$A$16:$A$18,0))) -> 3 | G11: =IF(A11="","",WORKDAY(B11,F11)) -> 46276
A12: 1000011 | B12: 46273 | C12: Standard | D12: East | E12: 0.8 | F12: =IF(A12="","",INDEX(Assumptions!$B$16:$B$18,MATCH(C12,Assumptions!$A$16:$A$18,0))) -> 3 | G12: =IF(A12="","",WORKDAY(B12,F12)) -> 46276
A13: 1000012 | B13: 46273 | C13: Express | D13: North | E13: 1.8 | F13: =IF(A13="","",INDEX(Assumptions!$B$16:$B$18,MATCH(C13,Assumptions!$A$16:$A$18,0))) -> 1 | G13: =IF(A13="","",WORKDAY(B13,F13)) -> 46274
... A9135: 1009134 | B9135: 46312 | C9135: Standard | D9135: North | E9135: 1.1 | F9135: =IF(A9135="","",INDEX(Assumptions!$B$16:$B$18,MATCH(C9135,Assumptions!$A$16:$A$18,0))) -> 3 | G9135: =IF(A9135="","",WORKDAY(B9135,F9135)) -> 46316
F9136: =IF(A9136="","",INDEX(Assumptions!$B$16:$B$18,MATCH(C9136,Assumptions!$A$16:$A$18,0))) | G9136: =IF(A9136="","",WORKDAY(B9136,F9136))
F9137: =IF(A9137="","",INDEX(Assumptions!$B$16:$B$18,MATCH(C9137,Assumptions!$A$16:$A$18,0))) | G9137: =IF(A9137="","",WORKDAY(B9137,F9137))
F9138: =IF(A9138="","",INDEX(Assumptions!$B$16:$B$18,MATCH(C9138,Assumptions!$A$16:$A$18,0))) | G9138: =IF(A9138="","",WORKDAY(B9138,F9138))
F9139: =IF(A9139="","",INDEX(Assumptions!$B$16:$B$18,MATCH(C9139,Assumptions!$A$16:$A$18,0))) | G9139: =IF(A9139="","",WORKDAY(B9139,F9139))
F9140: =IF(A9140="","",INDEX(Assumptions!$B$16:$B$18,MATCH(C9140,Assumptions!$A$16:$A$18,0))) | G9140: =IF(A9140="","",WORKDAY(B9140,F9140))
F9141: =IF(A9141="","",INDEX(Assumptions!$B$16:$B$18,MATCH(C9141,Assumptions!$A$16:$A$18,0))) | G9141: =IF(A9141="","",WORKDAY(B9141,F9141))
F9142: =IF(A9142="","",INDEX(Assumptions!$B$16:$B$18,MATCH(C9142,Assumptions!$A$16:$A$18,0))) | G9142: =IF(A9142="","",WORKDAY(B9142,F9142))
F9143: =IF(A9143="","",INDEX(Assumptions!$B$16:$B$18,MATCH(C9143,Assumptions!$A$16:$A$18,0))) | G9143: =IF(A9143="","",WORKDAY(B9143,F9143))
F9144: =IF(A9144="","",INDEX(Assumptions!$B$16:$B$18,MATCH(C9144,Assumptions!$A$16:$A$18,0))) | G9144: =IF(A9144="","",WORKDAY(B9144,F9144))
F9145: =IF(A9145="","",INDEX(Assumptions!$B$16:$B$18,MATCH(C9145,Assumptions!$A$16:$A$18,0))) | G9145: =IF(A9145="","",WORKDAY(B9145,F9145))
F9146: =IF(A9146="","",INDEX(Assumptions!$B$16:$B$18,MATCH(C9146,Assumptions!$A$16:$A$18,0))) | G9146: =IF(A9146="","",WORKDAY(B9146,F9146))
F9147: =IF(A9147="","",INDEX(Assumptions!$B$16:$B$18,MATCH(C9147,Assumptions!$A$16:$A$18,0))) | G9147: =IF(A9147="","",WORKDAY(B9147,F9147))
... F15001: =IF(A15001="","",INDEX(Assumptions!$B$16:$B$18,MATCH(C15001,Assumptions!$A$16:$A$18,0))) | G15001: =IF(A15001="","",WORKDAY(B15001,F15001))

Sheet Attempts
A1: Parcel ID | B1: Attempt Date | C1: Attempt No (0 = not attempted) | D1: Outcome | E1: Failure Reason | F1: Parcel Row (calc) | G1: Service (calc) | H1: Zone (calc) | I1: Delivered On Time (calc)
A2: 1000001 | B2: 46273 | C2: 1 | D2: Delivered | F2: =IF(A2="","",MATCH(A2,P_ID,1)) -> 1 | G2: =IF(A2="","",INDEX(P_Svc,F2)) -> Express | H2: =IF(A2="","",INDEX(P_Zone,F2)) -> North | I2: =IF(A2="","",IF(D2="Delivered",IF(B2<=INDEX(P_Due,F2),1,0),0)) -> 1
A3: 1000025 | B3: 46273 | C3: 1 | D3: Delivered | F3: =IF(A3="","",MATCH(A3,P_ID,1)) -> 25 | G3: =IF(A3="","",INDEX(P_Svc,F3)) -> Express | H3: =IF(A3="","",INDEX(P_Zone,F3)) -> North | I3: =IF(A3="","",IF(D3="Delivered",IF(B3<=INDEX(P_Due,F3),1,0),0)) -> 1
A4: 1000026 | B4: 46273 | C4: 1 | D4: Delivered | F4: =IF(A4="","",MATCH(A4,P_ID,1)) -> 26 | G4: =IF(A4="","",INDEX(P_Svc,F4)) -> Express | H4: =IF(A4="","",INDEX(P_Zone,F4)) -> North | I4: =IF(A4="","",IF(D4="Delivered",IF(B4<=INDEX(P_Due,F4),1,0),0)) -> 1
A5: 1000054 | B5: 46273 | C5: 1 | D5: Delivered | F5: =IF(A5="","",MATCH(A5,P_ID,1)) -> 54 | G5: =IF(A5="","",INDEX(P_Svc,F5)) -> Express | H5: =IF(A5="","",INDEX(P_Zone,F5)) -> East | I5: =IF(A5="","",IF(D5="Delivered",IF(B5<=INDEX(P_Due,F5),1,0),0)) -> 1
A6: 1000059 | B6: 46273 | C6: 1 | D6: Delivered | F6: =IF(A6="","",MATCH(A6,P_ID,1)) -> 59 | G6: =IF(A6="","",INDEX(P_Svc,F6)) -> Express | H6: =IF(A6="","",INDEX(P_Zone,F6)) -> Central | I6: =IF(A6="","",IF(D6="Delivered",IF(B6<=INDEX(P_Due,F6),1,0),0)) -> 1
A7: 1000082 | B7: 46273 | C7: 1 | D7: Delivered | F7: =IF(A7="","",MATCH(A7,P_ID,1)) -> 82 | G7: =IF(A7="","",INDEX(P_Svc,F7)) -> Express | H7: =IF(A7="","",INDEX(P_Zone,F7)) -> South | I7: =IF(A7="","",IF(D7="Delivered",IF(B7<=INDEX(P_Due,F7),1,0),0)) -> 1
A8: 1000099 | B8: 46273 | C8: 1 | D8: Failed | E8: Customer not home | F8: =IF(A8="","",MATCH(A8,P_ID,1)) -> 99 | G8: =IF(A8="","",INDEX(P_Svc,F8)) -> Express | H8: =IF(A8="","",INDEX(P_Zone,F8)) -> East | I8: =IF(A8="","",IF(D8="Delivered",IF(B8<=INDEX(P_Due,F8),1,0),0)) -> 0
A9: 1000100 | B9: 46273 | C9: 1 | D9: Delivered | F9: =IF(A9="","",MATCH(A9,P_ID,1)) -> 100 | G9: =IF(A9="","",INDEX(P_Svc,F9)) -> Express | H9: =IF(A9="","",INDEX(P_Zone,F9)) -> North | I9: =IF(A9="","",IF(D9="Delivered",IF(B9<=INDEX(P_Due,F9),1,0),0)) -> 1
A10: 1000103 | B10: 46273 | C10: 1 | D10: Delivered | F10: =IF(A10="","",MATCH(A10,P_ID,1)) -> 103 | G10: =IF(A10="","",INDEX(P_Svc,F10)) -> Express | H10: =IF(A10="","",INDEX(P_Zone,F10)) -> West | I10: =IF(A10="","",IF(D10="Delivered",IF(B10<=INDEX(P_Due,F10),1,0),0)) -> 1
A11: 1000106 | B11: 46273 | C11: 1 | D11: Delivered | F11: =IF(A11="","",MATCH(A11,P_ID,1)) -> 106 | G11: =IF(A11="","",INDEX(P_Svc,F11)) -> Express | H11: =IF(A11="","",INDEX(P_Zone,F11)) -> West | I11: =IF(A11="","",IF(D11="Delivered",IF(B11<=INDEX(P_Due,F11),1,0),0)) -> 1
A12: 1000111 | B12: 46273 | C12: 1 | D12: Delivered | F12: =IF(A12="","",MATCH(A12,P_ID,1)) -> 111 | G12: =IF(A12="","",INDEX(P_Svc,F12)) -> Express | H12: =IF(A12="","",INDEX(P_Zone,F12)) -> South | I12: =IF(A12="","",IF(D12="Delivered",IF(B12<=INDEX(P_Due,F12),1,0),0)) -> 1
A13: 1000142 | B13: 46273 | C13: 1 | D13: Failed | E13: Customer not home | F13: =IF(A13="","",MATCH(A13,P_ID,1)) -> 142 | G13: =IF(A13="","",INDEX(P_Svc,F13)) -> Express | H13: =IF(A13="","",INDEX(P_Zone,F13)) -> North | I13: =IF(A13="","",IF(D13="Delivered",IF(B13<=INDEX(P_Due,F13),1,0),0)) -> 0
A14: 1000180 | B14: 46273 | C14: 1 | D14: Delivered | F14: =IF(A14="","",MATCH(A14,P_ID,1)) -> 180 | G14: =IF(A14="","",INDEX(P_Svc,F14)) -> Express | H14: =IF(A14="","",INDEX(P_Zone,F14)) -> North | I14: =IF(A14="","",IF(D14="Delivered",IF(B14<=INDEX(P_Due,F14),1,0),0)) -> 1
A15: 1000217 | B15: 46273 | C15: 1 | D15: Delivered | F15: =IF(A15="","",MATCH(A15,P_ID,1)) -> 217 | G15: =IF(A15="","",INDEX(P_Svc,F15)) -> Express | H15: =IF(A15="","",INDEX(P_Zone,F15)) -> North | I15: =IF(A15="","",IF(D15="Delivered",IF(B15<=INDEX(P_Due,F15),1,0),0)) -> 1
A16: 1000221 | B16: 46273 | C16: 1 | D16: Delivered | F16: =IF(A16="","",MATCH(A16,P_ID,1)) -> 221 | G16: =IF(A16="","",INDEX(P_Svc,F16)) -> Express | H16: =IF(A16="","",INDEX(P_Zone,F16)) -> South | I16: =IF(A16="","",IF(D16="Delivered",IF(B16<=INDEX(P_Due,F16),1,0),0)) -> 1
A17: 1000252 | B17: 46273 | C17: 1 | D17: Delivered | F17: =IF(A17="","",MATCH(A17,P_ID,1)) -> 252 | G17: =IF(A17="","",INDEX(P_Svc,F17)) -> Express | H17: =IF(A17="","",INDEX(P_Zone,F17)) -> East | I17: =IF(A17="","",IF(D17="Delivered",IF(B17<=INDEX(P_Due,F17),1,0),0)) -> 1
A18: 1000253 | B18: 46273 | C18: 1 | D18: Failed | E18: Customer not home | F18: =IF(A18="","",MATCH(A18,P_ID,1)) -> 253 | G18: =IF(A18="","",INDEX(P_Svc,F18)) -> Express | H18: =IF(A18="","",INDEX(P_Zone,F18)) -> West | I18: =IF(A18="","",IF(D18="Delivered",IF(B18<=INDEX(P_Due,F18),1,0),0)) -> 0
A19: 1000257 | B19: 46273 | C19: 1 | D19: Delivered | F19: =IF(A19="","",MATCH(A19,P_ID,1)) -> 257 | G19: =IF(A19="","",INDEX(P_Svc,F19)) -> Express | H19: =IF(A19="","",INDEX(P_Zone,F19)) -> West | I19: =IF(A19="","",IF(D19="Delivered",IF(B19<=INDEX(P_Due,F19),1,0),0)) -> 1
A20: 1000055 | B20: 46273 | C20: 1 | D20: Delivered | F20: =IF(A20="","",MATCH(A20,P_ID,1)) -> 55 | G20: =IF(A20="","",INDEX(P_Svc,F20)) -> Express | H20: =IF(A20="","",INDEX(P_Zone,F20)) -> North | I20: =IF(A20="","",IF(D20="Delivered",IF(B20<=INDEX(P_Due,F20),1,0),0)) -> 1
A21: 1000120 | B21: 46273 | C21: 1 | D21: Delivered | F21: =IF(A21="","",MATCH(A21,P_ID,1)) -> 120 | G21: =IF(A21="","",INDEX(P_Svc,F21)) -> Express | H21: =IF(A21="","",INDEX(P_Zone,F21)) -> East | I21: =IF(A21="","",IF(D21="Delivered",IF(B21<=INDEX(P_Due,F21),1,0),0)) -> 1
A22: 1000130 | B22: 46273 | C22: 1 | D22: Delivered | F22: =IF(A22="","",MATCH(A22,P_ID,1)) -> 130 | G22: =IF(A22="","",INDEX(P_Svc,F22)) -> Express | H22: =IF(A22="","",INDEX(P_Zone,F22)) -> Central | I22: =IF(A22="","",IF(D22="Delivered",IF(B22<=INDEX(P_Due,F22),1,0),0)) -> 1
A23: 1000209 | B23: 46273 | C23: 1 | D23: Delivered | F23: =IF(A23="","",MATCH(A23,P_ID,1)) -> 209 | G23: =IF(A23="","",INDEX(P_Svc,F23)) -> Express | H23: =IF(A23="","",INDEX(P_Zone,F23)) -> North | I23: =IF(A23="","",IF(D23="Delivered",IF(B23<=INDEX(P_Due,F23),1,0),0)) -> 1
A24: 1000222 | B24: 46273 | C24: 1 | D24: Delivered | F24: =IF(A24="","",MATCH(A24,P_ID,1)) -> 222 | G24: =IF(A24="","",INDEX(P_Svc,F24)) -> Express | H24: =IF(A24="","",INDEX(P_Zone,F24)) -> East | I24: =IF(A24="","",IF(D24="Delivered",IF(B24<=INDEX(P_Due,F24),1,0),0)) -> 1
A25: 1000225 | B25: 46273 | C25: 1 | D25: Delivered | F25: =IF(A25="","",MATCH(A25,P_ID,1)) -> 225 | G25: =IF(A25="","",INDEX(P_Svc,F25)) -> Express | H25: =IF(A25="","",INDEX(P_Zone,F25)) -> Central | I25: =IF(A25="","",IF(D25="Delivered",IF(B25<=INDEX(P_Due,F25),1,0),0)) -> 1
A26: 1000228 | B26: 46273 | C26: 1 | D26: Delivered | F26: =IF(A26="","",MATCH(A26,P_ID,1)) -> 228 | G26: =IF(A26="","",INDEX(P_Svc,F26)) -> Express | H26: =IF(A26="","",INDEX(P_Zone,F26)) -> East | I26: =IF(A26="","",IF(D26="Delivered",IF(B26<=INDEX(P_Due,F26),1,0),0)) -> 1
A27: 1000233 | B27: 46273 | C27: 1 | D27: Failed | E27: Address issue | F27: =IF(A27="","",MATCH(A27,P_ID,1)) -> 233 | G27: =IF(A27="","",INDEX(P_Svc,F27)) -> Express | H27: =IF(A27="","",INDEX(P_Zone,F27)) -> South | I27: =IF(A27="","",IF(D27="Delivered",IF(B27<=INDEX(P_Due,F27),1,0),0)) -> 0
A28: 1000243 | B28: 46273 | C28: 1 | D28: Delivered | F28: =IF(A28="","",MATCH(A28,P_ID,1)) -> 243 | G28: =IF(A28="","",INDEX(P_Svc,F28)) -> Express | H28: =IF(A28="","",INDEX(P_Zone,F28)) -> South | I28: =IF(A28="","",IF(D28="Delivered",IF(B28<=INDEX(P_Due,F28),1,0),0)) -> 1
A29: 1000012 | B29: 46274 | C29: 1 | D29: Delivered | F29: =IF(A29="","",MATCH(A29,P_ID,1)) -> 12 | G29: =IF(A29="","",INDEX(P_Svc,F29)) -> Express | H29: =IF(A29="","",INDEX(P_Zone,F29)) -> North | I29: =IF(A29="","",IF(D29="Delivered",IF(B29<=INDEX(P_Due,F29),1,0),0)) -> 1
A30: 1000013 | B30: 46274 | C30: 1 | D30: Delivered | F30: =IF(A30="","",MATCH(A30,P_ID,1)) -> 13 | G30: =IF(A30="","",INDEX(P_Svc,F30)) -> Express | H30: =IF(A30="","",INDEX(P_Zone,F30)) -> East | I30: =IF(A30="","",IF(D30="Delivered",IF(B30<=INDEX(P_Due,F30),1,0),0)) -> 1
A31: 1000016 | B31: 46274 | C31: 1 | D31: Delivered | F31: =IF(A31="","",MATCH(A31,P_ID,1)) -> 16 | G31: =IF(A31="","",INDEX(P_Svc,F31)) -> Express | H31: =IF(A31="","",INDEX(P_Zone,F31)) -> West | I31: =IF(A31="","",IF(D31="Delivered",IF(B31<=INDEX(P_Due,F31),1,0),0)) -> 1
A32: 1000041 | B32: 46274 | C32: 1 | D32: Failed | E32: Customer not home | F32: =IF(A32="","",MATCH(A32,P_ID,1)) -> 41 | G32: =IF(A32="","",INDEX(P_Svc,F32)) -> Express | H32: =IF(A32="","",INDEX(P_Zone,F32)) -> Central | I32: =IF(A32="","",IF(D32="Delivered",IF(B32<=INDEX(P_Due,F32),1,0),0)) -> 0
A33: 1000043 | B33: 46274 | C33: 1 | D33: Delivered | F33: =IF(A33="","",MATCH(A33,P_ID,1)) -> 43 | G33: =IF(A33="","",INDEX(P_Svc,F33)) -> Express | H33: =IF(A33="","",INDEX(P_Zone,F33)) -> West | I33: =IF(A33="","",IF(D33="Delivered",IF(B33<=INDEX(P_Due,F33),1,0),0)) -> 1
A34: 1000056 | B34: 46274 | C34: 1 | D34: Delivered | F34: =IF(A34="","",MATCH(A34,P_ID,1)) -> 56 | G34: =IF(A34="","",INDEX(P_Svc,F34)) -> Express | H34: =IF(A34="","",INDEX(P_Zone,F34)) -> East | I34: =IF(A34="","",IF(D34="Delivered",IF(B34<=INDEX(P_Due,F34),1,0),0)) -> 1
A35: 1000063 | B35: 46274 | C35: 1 | D35: Failed | E35: Customer not home | F35: =IF(A35="","",MATCH(A35,P_ID,1)) -> 63 | G35: =IF(A35="","",INDEX(P_Svc,F35)) -> Express | H35: =IF(A35="","",INDEX(P_Zone,F35)) -> North | I35: =IF(A35="","",IF(D35="Delivered",IF(B35<=INDEX(P_Due,F35),1,0),0)) -> 0
A36: 1000091 | B36: 46274 | C36: 1 | D36: Delivered | F36: =IF(A36="","",MATCH(A36,P_ID,1)) -> 91 | G36: =IF(A36="","",INDEX(P_Svc,F36)) -> Express | H36: =IF(A36="","",INDEX(P_Zone,F36)) -> Central | I36: =IF(A36="","",IF(D36="Delivered",IF(B36<=INDEX(P_Due,F36),1,0),0)) -> 1
A37: 1000165 | B37: 46274 | C37: 1 | D37: Delivered | F37: =IF(A37="","",MATCH(A37,P_ID,1)) -> 165 | G37: =IF(A37="","",INDEX(P_Svc,F37)) -> Express | H37: =IF(A37="","",INDEX(P_Zone,F37)) -> Central | I37: =IF(A37="","",IF(D37="Delivered",IF(B37<=INDEX(P_Due,F37),1,0),0)) -> 1
A38: 1000170 | B38: 46274 | C38: 1 | D38: Delivered | F38: =IF(A38="","",MATCH(A38,P_ID,1)) -> 170 | G38: =IF(A38="","",INDEX(P_Svc,F38)) -> Express | H38: =IF(A38="","",INDEX(P_Zone,F38)) -> Central | I38: =IF(A38="","",IF(D38="Delivered",IF(B38<=INDEX(P_Due,F38),1,0),0)) -> 1
A39: 1000192 | B39: 46274 | C39: 1 | D39: Delivered | F39: =IF(A39="","",MATCH(A39,P_ID,1)) -> 192 | G39: =IF(A39="","",INDEX(P_Svc,F39)) -> Express | H39: =IF(A39="","",INDEX(P_Zone,F39)) -> Central | I39: =IF(A39="","",IF(D39="Delivered",IF(B39<=INDEX(P_Due,F39),1,0),0)) -> 1
A40: 1000195 | B40: 46274 | C40: 1 | D40: Delivered | F40: =IF(A40="","",MATCH(A40,P_ID,1)) -> 195 | G40: =IF(A40="","",INDEX(P_Svc,F40)) -> Express | H40: =IF(A40="","",INDEX(P_Zone,F40)) -> Central | I40: =IF(A40="","",IF(D40="Delivered",IF(B40<=INDEX(P_Due,F40),1,0),0)) -> 1
...

Sheet Assumptions
A1: Assumptions & Controls
A3: Hub name | B3: Northgate Sort Hub (fictitious)
A4: Hub code | B4: NGH-01
A5: Report date override (leave blank = latest data)
A6: Report date used (formula) | B6: =IF(ISNUMBER(B5),B5,MAX(A_Date)) -> 46312
A7: Delivery SLA target (% delivered on time) | B7: 0.95
A8: Attempt rate target (attempted / out for delivery) | B8: 0.97
A9: First-attempt delivery target | B9: 0.88
A10: Backlog alert (days of average intake) | B10: 1.5
A11: Service filter criterion (from Summary) | B11: =IF(Summary!B3="All","*",Summary!B3) -> *
A12: Zone filter criterion (from Summary) | B12: =IF(Summary!F3="All","*",Summary!F3) -> *
A14: SLA by service level
A15: Service | B15: SLA (business days from receipt)
A16: Express | B16: 1
A17: Standard | B17: 3
A18: Economy | B18: 5
A20: Metric definitions
A21: Received = parcels scanned in at the hub on the day (Parcels sheet).
A22: Out for delivery = parcels loaded on vans that day (every row in Attempts for that date).
A23: Attempted = out for delivery minus rows with outcome 'Not attempted' (route cut-off).
A24: Attempt rate = Attempted / Out for delivery.
A25: Delivery SLA % = parcels delivered on or before their due date / parcels delivered that day.
A26: Due date = received date + SLA business days (Mon to Fri, WORKDAY). Hub operates Mon to Sat.
A27: First-attempt delivery rate = delivered on attempt 1 / parcels on attempt 1.
A28: Closing backlog = all parcels received up to the day minus all delivered up to the day.
A29: Backlog is only correct if the Parcels sheet holds every parcel not yet delivered.
A31: Blue on yellow = input. Black = formula. Sample parcel and attempt records are randomly simulated.

Sheet How To Use
A1: How this dashboard refreshes itself
A3: Daily refresh (about 1 minute)
A4: 1. Export yesterday's inbound scans and delivery-attempt events from your hub system.
A5: 2. Paste new inbound rows at the bottom of 'Parcels' (columns A to E only: ID, received date, service, zone, weight).
A6: 3. Paste new attempt rows at the bottom of 'Attempts' (columns A to E only: ID, date, attempt no, outcome, failure reason).
A7: 4. Open 'Summary'. The window rolls forward to the latest date automatically. Nothing else to touch.
A8: (Or drop the CSV exports in data/raw and run: make refresh)
A10: What updates automatically
A11: - Report date: set to the latest attempt date unless you type an override in Assumptions B5.
A12: - Rolling 30 operating days (Mon to Sat), KPIs, snapshot, zone table, exception table, all four charts and the text observations.
A13: - SLA due dates and on-time flags (black formula columns in Parcels and Attempts, pre-filled for future rows).
A14: - Service and Zone drop-downs on Summary re-cut every number and chart.
... A22: - Backlog assumes 'Parcels' holds every parcel received and not yet delivered.
